[2025-02-20T06:57:11.527+0000] {local_task_job_runner.py:123} INFO - ::group::Pre task execution logs
[2025-02-20T06:57:11.553+0000] {taskinstance.py:2613} INFO - Dependencies all met for dep_context=non-requeueable deps ti=<TaskInstance: dag_failure_alert.failing_task1 manual__2025-02-20T06:57:05.088126+00:00 [queued]>
[2025-02-20T06:57:11.563+0000] {taskinstance.py:2613} INFO - Dependencies all met for dep_context=requeueable deps ti=<TaskInstance: dag_failure_alert.failing_task1 manual__2025-02-20T06:57:05.088126+00:00 [queued]>
[2025-02-20T06:57:11.564+0000] {taskinstance.py:2866} INFO - Starting attempt 1 of 1
[2025-02-20T06:57:11.581+0000] {taskinstance.py:2889} INFO - Executing <Task(PythonOperator): failing_task1> on 2025-02-20 06:57:05.088126+00:00
[2025-02-20T06:57:11.596+0000] {warnings.py:112} WARNING - /home/***/.local/lib/python3.12/site-packages/***/task/task_runner/standard_task_runner.py:70: DeprecationWarning: This process (pid=88) is multi-threaded, use of fork() may lead to deadlocks in the child.
  pid = os.fork()

[2025-02-20T06:57:11.598+0000] {standard_task_runner.py:72} INFO - Started process 90 to run task
[2025-02-20T06:57:11.598+0000] {standard_task_runner.py:104} INFO - Running: ['***', 'tasks', 'run', 'dag_failure_alert', 'failing_task1', 'manual__2025-02-20T06:57:05.088126+00:00', '--job-id', '220', '--raw', '--subdir', 'DAGS_FOLDER/failing_dag.py', '--cfg-path', '/tmp/tmpg1jdrn4b']
[2025-02-20T06:57:11.600+0000] {standard_task_runner.py:105} INFO - Job 220: Subtask failing_task1
[2025-02-20T06:57:11.665+0000] {task_command.py:467} INFO - Running <TaskInstance: dag_failure_alert.failing_task1 manual__2025-02-20T06:57:05.088126+00:00 [running]> on host 220b767f943b
[2025-02-20T06:57:11.762+0000] {taskinstance.py:3132} INFO - Exporting env vars: AIRFLOW_CTX_DAG_EMAIL='benhur.harrison@zemosolabs.com' AIRFLOW_CTX_DAG_OWNER='***' AIRFLOW_CTX_DAG_ID='dag_failure_alert' AIRFLOW_CTX_TASK_ID='failing_task1' AIRFLOW_CTX_EXECUTION_DATE='2025-02-20T06:57:05.088126+00:00' AIRFLOW_CTX_TRY_NUMBER='1' AIRFLOW_CTX_DAG_RUN_ID='manual__2025-02-20T06:57:05.088126+00:00'
[2025-02-20T06:57:11.763+0000] {logging_mixin.py:190} INFO - Task instance is in running state
[2025-02-20T06:57:11.763+0000] {logging_mixin.py:190} INFO -  Previous state of the Task instance: queued
[2025-02-20T06:57:11.763+0000] {logging_mixin.py:190} INFO - Current task name:failing_task1 state:running start_date:2025-02-20 06:57:11.553814+00:00
[2025-02-20T06:57:11.763+0000] {logging_mixin.py:190} INFO - Dag name:dag_failure_alert and current dag run status:running
[2025-02-20T06:57:11.764+0000] {taskinstance.py:731} INFO - ::endgroup::
[2025-02-20T06:57:11.764+0000] {taskinstance.py:3311} ERROR - Task failed with exception
Traceback (most recent call last):
  File "/home/airflow/.local/lib/python3.12/site-packages/airflow/models/taskinstance.py", line 767, in _execute_task
    result = _execute_callable(context=context, **execute_callable_kwargs)
             ^^^^^^^^^^^^^^^^^^^^^^^^^^^^^^^^^^^^^^^^^^^^^^^^^^^^^^^^^^^^^
  File "/home/airflow/.local/lib/python3.12/site-packages/airflow/models/taskinstance.py", line 733, in _execute_callable
    return ExecutionCallableRunner(
           ^^^^^^^^^^^^^^^^^^^^^^^^
  File "/home/airflow/.local/lib/python3.12/site-packages/airflow/utils/operator_helpers.py", line 252, in run
    return self.func(*args, **kwargs)
           ^^^^^^^^^^^^^^^^^^^^^^^^^^
  File "/home/airflow/.local/lib/python3.12/site-packages/airflow/models/baseoperator.py", line 422, in wrapper
    return func(self, *args, **kwargs)
           ^^^^^^^^^^^^^^^^^^^^^^^^^^^
  File "/home/airflow/.local/lib/python3.12/site-packages/airflow/operators/python.py", line 238, in execute
    return_value = self.execute_callable()
                   ^^^^^^^^^^^^^^^^^^^^^^^
  File "/home/airflow/.local/lib/python3.12/site-packages/airflow/operators/python.py", line 256, in execute_callable
    return runner.run(*self.op_args, **self.op_kwargs)
           ^^^^^^^^^^^^^^^^^^^^^^^^^^^^^^^^^^^^^^^^^^^
  File "/home/airflow/.local/lib/python3.12/site-packages/airflow/utils/operator_helpers.py", line 252, in run
    return self.func(*args, **kwargs)
           ^^^^^^^^^^^^^^^^^^^^^^^^^^
  File "/opt/airflow/dags/failing_dag.py", line 8, in failing_task
    raise Exception("This task failed!")
Exception: This task failed!
[2025-02-20T06:57:11.777+0000] {logging_mixin.py:190} INFO - Task instance in failure state
[2025-02-20T06:57:11.777+0000] {logging_mixin.py:190} INFO - Task start:2025-02-20 06:57:11.553814+00:00 end:2025-02-20 06:57:11.776593+00:00 duration:0.222779
[2025-02-20T06:57:11.777+0000] {logging_mixin.py:190} INFO - Task:<Task(PythonOperator): failing_task1> dag:<DAG: dag_failure_alert> dagrun:<DagRun dag_failure_alert @ 2025-02-20 06:57:05.088126+00:00: manual__2025-02-20T06:57:05.088126+00:00, state:running, queued_at: 2025-02-20 06:57:05.109333+00:00. externally triggered: True>
[2025-02-20T06:57:11.778+0000] {logging_mixin.py:190} INFO - Failure caused by This task failed!
[2025-02-20T06:57:11.778+0000] {taskinstance.py:1225} INFO - Marking task as FAILED. dag_id=dag_failure_alert, task_id=failing_task1, run_id=manual__2025-02-20T06:57:05.088126+00:00, execution_date=20250220T065705, start_date=20250220T065711, end_date=20250220T065711
[2025-02-20T06:57:11.793+0000] {warnings.py:112} WARNING - /home/***/.local/lib/python3.12/site-packages/***/utils/email.py:155: RemovedInAirflow3Warning: Fetching SMTP credentials from configuration variables will be deprecated in a future release. Please set credentials using a connection instead.
  send_mime_email(e_from=mail_from, e_to=recipients, mime_msg=msg, conn_id=conn_id, dryrun=dryrun)

[2025-02-20T06:57:11.793+0000] {email.py:272} INFO - Email alerting: attempt 1
[2025-02-20T06:57:15.523+0000] {email.py:283} INFO - Sent an alert email to ['benhur.harrison@zemosolabs.com']
[2025-02-20T06:57:17.279+0000] {taskinstance.py:340} INFO - ::group::Post task execution logs
[2025-02-20T06:57:17.280+0000] {standard_task_runner.py:124} ERROR - Failed to execute job 220 for task failing_task1 (This task failed!; 90)
Traceback (most recent call last):
  File "/home/airflow/.local/lib/python3.12/site-packages/airflow/task/task_runner/standard_task_runner.py", line 117, in _start_by_fork
    ret = args.func(args, dag=self.dag)
          ^^^^^^^^^^^^^^^^^^^^^^^^^^^^^
  File "/home/airflow/.local/lib/python3.12/site-packages/airflow/cli/cli_config.py", line 49, in command
    return func(*args, **kwargs)
           ^^^^^^^^^^^^^^^^^^^^^
  File "/home/airflow/.local/lib/python3.12/site-packages/airflow/utils/cli.py", line 116, in wrapper
    return f(*args, **kwargs)
           ^^^^^^^^^^^^^^^^^^
  File "/home/airflow/.local/lib/python3.12/site-packages/airflow/cli/commands/task_command.py", line 483, in task_run
    task_return_code = _run_task_by_selected_method(args, _dag, ti)
                       ^^^^^^^^^^^^^^^^^^^^^^^^^^^^^^^^^^^^^^^^^^^^
  File "/home/airflow/.local/lib/python3.12/site-packages/airflow/cli/commands/task_command.py", line 256, in _run_task_by_selected_method
    return _run_raw_task(args, ti)
           ^^^^^^^^^^^^^^^^^^^^^^^
  File "/home/airflow/.local/lib/python3.12/site-packages/airflow/cli/commands/task_command.py", line 341, in _run_raw_task
    return ti._run_raw_task(
           ^^^^^^^^^^^^^^^^^
  File "/home/airflow/.local/lib/python3.12/site-packages/airflow/utils/session.py", line 97, in wrapper
    return func(*args, session=session, **kwargs)
           ^^^^^^^^^^^^^^^^^^^^^^^^^^^^^^^^^^^^^^
  File "/home/airflow/.local/lib/python3.12/site-packages/airflow/models/taskinstance.py", line 3005, in _run_raw_task
    return _run_raw_task(
           ^^^^^^^^^^^^^^
  File "/home/airflow/.local/lib/python3.12/site-packages/airflow/models/taskinstance.py", line 273, in _run_raw_task
    TaskInstance._execute_task_with_callbacks(
  File "/home/airflow/.local/lib/python3.12/site-packages/airflow/models/taskinstance.py", line 3159, in _execute_task_with_callbacks
    result = self._execute_task(context, task_orig)
             ^^^^^^^^^^^^^^^^^^^^^^^^^^^^^^^^^^^^^^
  File "/home/airflow/.local/lib/python3.12/site-packages/airflow/models/taskinstance.py", line 3183, in _execute_task
    return _execute_task(self, context, task_orig)
           ^^^^^^^^^^^^^^^^^^^^^^^^^^^^^^^^^^^^^^^
  File "/home/airflow/.local/lib/python3.12/site-packages/airflow/models/taskinstance.py", line 767, in _execute_task
    result = _execute_callable(context=context, **execute_callable_kwargs)
             ^^^^^^^^^^^^^^^^^^^^^^^^^^^^^^^^^^^^^^^^^^^^^^^^^^^^^^^^^^^^^
  File "/home/airflow/.local/lib/python3.12/site-packages/airflow/models/taskinstance.py", line 733, in _execute_callable
    return ExecutionCallableRunner(
           ^^^^^^^^^^^^^^^^^^^^^^^^
  File "/home/airflow/.local/lib/python3.12/site-packages/airflow/utils/operator_helpers.py", line 252, in run
    return self.func(*args, **kwargs)
           ^^^^^^^^^^^^^^^^^^^^^^^^^^
  File "/home/airflow/.local/lib/python3.12/site-packages/airflow/models/baseoperator.py", line 422, in wrapper
    return func(self, *args, **kwargs)
           ^^^^^^^^^^^^^^^^^^^^^^^^^^^
  File "/home/airflow/.local/lib/python3.12/site-packages/airflow/operators/python.py", line 238, in execute
    return_value = self.execute_callable()
                   ^^^^^^^^^^^^^^^^^^^^^^^
  File "/home/airflow/.local/lib/python3.12/site-packages/airflow/operators/python.py", line 256, in execute_callable
    return runner.run(*self.op_args, **self.op_kwargs)
           ^^^^^^^^^^^^^^^^^^^^^^^^^^^^^^^^^^^^^^^^^^^
  File "/home/airflow/.local/lib/python3.12/site-packages/airflow/utils/operator_helpers.py", line 252, in run
    return self.func(*args, **kwargs)
           ^^^^^^^^^^^^^^^^^^^^^^^^^^
  File "/opt/airflow/dags/failing_dag.py", line 8, in failing_task
    raise Exception("This task failed!")
Exception: This task failed!
[2025-02-20T06:57:17.313+0000] {local_task_job_runner.py:266} INFO - Task exited with return code 1
[2025-02-20T06:57:17.330+0000] {taskinstance.py:3895} INFO - 0 downstream tasks scheduled from follow-on schedule check
[2025-02-20T06:57:17.331+0000] {local_task_job_runner.py:245} INFO - ::endgroup::
